Workbook

Sheet FuelConsumptionCo2
A1: MODELYEAR | B1: MAKE | C1: MODEL | D1: VEHICLECLASS | E1: ENGINESIZE | F1: CYLINDERS | G1: TRANSMISSION | H1: FUELTYPE | I1: FUELCONSUMPTION_CITY | J1: FUELCONSUMPTION_HWY | K1: FUELCONSUMPTION_COMB | L1: FUELCONSUMPTION_COMB_MPG | M1: CO2EMISSIONS | O1: xy | P1: x2
A2: 2014 | B2: TOYOTA | C2: PRIUS c | D2: COMPACT | E2: 1.5 | F2: 4 | G2: AV | H2: X | I2: 4.6 | J2: 4.9 | K2: 4.7 | L2: 60 | M2: 108 | O2: =M2*E2 -> 162 | P2: =E2*E2 -> 2.25
A3: 2014 | B3: HONDA | C3: ACCORD HYBRID | D3: MID-SIZE | E3: 2 | F3: 4 | G3: AV | H3: X | I3: 4.7 | J3: 4.9 | K3: 4.8 | L3: 59 | M3: 110 | O3: =M3*E3 -> 220 | P3: =E3*E3 -> 4
A4: 2014 | B4: TOYOTA | C4: PRIUS | D4: MID-SIZE | E4: 1.8 | F4: 4 | G4: AV | H4: X | I4: 4.7 | J4: 4.9 | K4: 4.8 | L4: 59 | M4: 110 | O4: =M4*E4 -> 198 | P4: =E4*E4 -> 3.24
A5: 2014 | B5: VOLKSWAGEN | C5: JETTA TURBO HYBRID | D5: COMPACT | E5: 1.4 | F5: 4 | G5: AM7 | H5: Z | I5: 5.6 | J5: 5.2 | K5: 5.4 | L5: 52 | M5: 124 | O5: =M5*E5 -> 173.6 | P5: =E5*E5 -> 1.96
A6: 2014 | B6: FORD | C6: FUSION HYBRID | D6: MID-SIZE | E6: 2 | F6: 4 | G6: AV | H6: X | I6: 5.3 | J6: 5.7 | K6: 5.5 | L6: 51 | M6: 126 | O6: =M6*E6 -> 252 | P6: =E6*E6 -> 4
A7: 2014 | B7: TOYOTA | C7: PRIUS v | D7: STATION WAGON - MID-SIZE | E7: 1.8 | F7: 4 | G7: AV | H7: X | I7: 5.3 | J7: 5.8 | K7: 5.5 | L7: 51 | M7: 126 | O7: =M7*E7 -> 226.8 | P7: =E7*E7 -> 3.24
A8: 2014 | B8: LEXUS | C8: CT 200h | D8: COMPACT | E8: 1.8 | F8: 4 | G8: AV | H8: X | I8: 5.5 | J8: 5.8 | K8: 5.6 | L8: 50 | M8: 129 | O8: =M8*E8 -> 232.2 | P8: =E8*E8 -> 3.24
A9: 2014 | B9: TOYOTA | C9: CAMRY HYBRID LE | D9: MID-SIZE | E9: 2.5 | F9: 4 | G9: AV | H9: X | I9: 5.5 | J9: 5.9 | K9: 5.7 | L9: 50 | M9: 131 | O9: =M9*E9 -> 327.5 | P9: =E9*E9 -> 6.25
A10: 2014 | B10: ACURA | C10: ILX HYBRID | D10: COMPACT | E10: 1.5 | F10: 4 | G10: AV7 | H10: Z | I10: 6 | J10: 5.8 | K10: 5.9 | L10: 48 | M10: 136 | O10: =M10*E10 -> 204 | P10: =E10*E10 -> 2.25
A11: 2014 | B11: FORD | C11: C-MAX HYBRID | D11: FULL-SIZE | E11: 2 | F11: 4 | G11: AV | H11: X | I11: 5.6 | J11: 6.4 | K11: 6 | L11: 47 | M11: 138 | O11: =M11*E11 -> 276 | P11: =E11*E11 -> 4
A12: 2014 | B12: LEXUS | C12: ES 300h | D12: MID-SIZE | E12: 2.5 | F12: 4 | G12: AV6 | H12: X | I12: 5.8 | J12: 6.2 | K12: 6 | L12: 47 | M12: 138 | O12: =M12*E12 -> 345 | P12: =E12*E12 -> 6.25
A13: 2014 | B13: MITSUBISHI | C13: MIRAGE | D13: COMPACT | E13: 1.2 | F13: 3 | G13: AV | H13: X | I13: 6.4 | J13: 5.4 | K13: 6 | L13: 47 | M13: 138 | O13: =M13*E13 -> 165.6 | P13: =E13*E13 -> 1.44
... A448: 2014 | B448: BMW | C448: 435i xDRIVE COUPE | D448: COMPACT | E448: 3 | F448: 6 | G448: M6 | H448: Z | I448: 11.9 | J448: 8.3 | K448: 10.3 | L448: 27 | M448: 237 | O448: =M448*E448 -> 711 | P448: =E448*E448 -> 9
A449: 2014 | B449: CHRYSLER | C449: 300 | D449: FULL-SIZE | E449: 3.6 | F449: 6 | G449: A8 | H449: X | I449: 12.4 | J449: 7.7 | K449: 10.3 | L449: 27 | M449: 237 | O449: =M449*E449 -> 853.2 | P449: =E449*E449 -> 12.96
A450: 2014 | B450: CHRYSLER | C450: 300 FFV | D450: FULL-SIZE | E450: 3.6 | F450: 6 | G450: A8 | H450: X | I450: 12.4 | J450: 7.7 | K450: 10.3 | L450: 27 | M450: 237 | O450: =M450*E450 -> 853.2 | P450: =E450*E450 -> 12.96
A451: 2014 | B451: DODGE | C451: CHARGER | D451: FULL-SIZE | E451: 3.6 | F451: 6 | G451: A8 | H451: X | I451: 12.4 | J451: 7.7 | K451: 10.3 | L451: 27 | M451: 237 | O451: =M451*E451 -> 853.2 | P451: =E451*E451 -> 12.96
A452: 2014 | B452: FORD | C452: FOCUS FFV | D452: COMPACT | E452: 2 | F452: 4 | G452: A6 | H452: E | I452: 11.7 | J452: 8.5 | K452: 10.3 | L452: 27 | M452: 165 | O452: =M452*E452 -> 330 | P452: =E452*E452 -> 4
A453: 2014 | B453: FORD | C453: FOCUS FFV | D453: COMPACT | E453: 2 | F453: 4 | G453: AS6 | H453: E | I453: 11.7 | J453: 8.5 | K453: 10.3 | L453: 27 | M453: 165 | O453: =M453*E453 -> 330 | P453: =E453*E453 -> 4
A454: 2014 | B454: FORD | C454: TAURUS FFV | D454: FULL-SIZE | E454: 3.5 | F454: 6 | G454: AS6 | H454: X | I454: 12.1 | J454: 8.1 | K454: 10.3 | L454: 27 | M454: 237 | O454: =M454*E454 -> 829.5 | P454: =E454*E454 -> 12.25
A455: 2014 | B455: HYUNDAI | C455: SANTA FE SPORT | D455: SUV - SMALL | E455: 2.4 | F455: 4 | G455: A6 | H455: X | I455: 11.6 | J455: 8.7 | K455: 10.3 | L455: 27 | M455: 237 | O455: =M455*E455 -> 568.8 | P455: =E455*E455 -> 5.76
A456: 2014 | B456: JAGUAR | C456: F-TYPE CONVERTIBLE | D456: TWO-SEATER | E456: 3 | F456: 6 | G456: AS8 | H456: Z | I456: 11.8 | J456: 8.4 | K456: 10.3 | L456: 27 | M456: 237 | O456: =M456*E456 -> 711 | P456: =E456*E456 -> 9
A457: 2014 | B457: KIA | C457: SORENTO | D457: SUV - SMALL | E457: 2.4 | F457: 4 | G457: A6 | H457: X | I457: 11.8 | J457: 8.5 | K457: 10.3 | L457: 27 | M457: 237 | O457: =M457*E457 -> 568.8 | P457: =E457*E457 -> 5.76
A458: 2014 | B458: MERCEDES-BENZ | C458: ML 350 BLUETEC 4MATIC | D458: SUV - STANDARD | E458: 3 | F458: 6 | G458: AS7 | H458: D | I458: 11.8 | J458: 8.5 | K458: 10.3 | L458: 27 | M458: 278 | O458: =M458*E458 -> 834 | P458: =E458*E458 -> 9
A459: 2014 | B459: PORSCHE | C459: 911 CARRERA 4 | D459: MINICOMPACT | E459: 3.4 | F459: 6 | G459: AM7 | H459: Z | I459: 11.8 | J459: 8.5 | K459: 10.3 | L459: 27 | M459: 237 | O459: =M459*E459 -> 805.8 | P459: =E459*E459 -> 11.56
A460: 2014 | B460: TOYOTA | C460: HIGHLANDER | D460: SUV - SMALL | E460: 2.7 | F460: 4 | G460: AS6 | H460: X | I460: 11.7 | J460: 8.6 | K460: 10.3 | L460: 27 | M460: 237 | O460: =M460*E460 -> 639.9 | P460: =E460*E460 -> 7.29
A461: 2014 | B461: ACURA | C461: TSX | D461: COMPACT | E461: 3.5 | F461: 6 | G461: AS5 | H461: Z | I461: 12.1 | J461: 8.3 | K461: 10.4 | L461: 27 | M461: 239 | O461: =M461*E461 -> 836.5 | P461: =E461*E461 -> 12.25
... A1068: 2014 | B1068: GMC | C1068: SAVANA 3500 PASSENGER | D1068: VAN - PASSENGER | E1068: 6 | F1068: 8 | G1068: A6 | H1068: E | I1068: 30.2 | J1068: 20.5 | K1068: 25.8 | L1068: 11 | M1068: 413 | O1068: =M1068*E1068 -> 2478 | P1068: =E1068*E1068 -> 36
E1069: total x | M1069: y | O1069: total xy
E1070: =SUM(E1:E1068) -> 3570.5 | M1070: =SUM(M1:M1068) -> 273396 | O1070: =SUM(O1:O1068) -> 998477.9

Sheet linear regression
C3: linear regression of | E3: engine size and CO2 Emission
C5: Let , | D5: X=Engine size
D6: y=Co2 Emission
D8: linear regression equation
D10: y = | E10: ax+b
D12: a | E12: slop
D13: b | E13: intercept, bias, error
D14: x | E14: regressor , predictor, feature, explanatory, input, independent variable
D15: y | E15: regressand, dependent, response, predicted variable
M16: n | N16: 1067
D17: we need to determine a, b then we can predict y . | N17: =SUM(FuelConsumptionCo2!E2:E1068) -> 3570.5
C19: let | N19: =SUM(FuelConsumptionCo2!M2:M1068) -> 273396
D21: slop | H21: =(N21-N30)/(N23-N25) -> 39.1252 | N21: =SUM(FuelConsumptionCo2!O2:O1068) -> 998477.9
N23: =SUM(FuelConsumptionCo2!P2:P1068) -> 14085.03
N25: =(N17*N17)/N16 -> 11947.957
D26: intercept | H26: =N28-N27*H21 -> 125.3041
N27: =AVERAGE(FuelConsumptionCo2!E2:E1068) -> 3.346298
N28: =AVERAGE(FuelConsumptionCo2!M2:M1068) -> 256.22868
D29: average
N30: =(N17*N19)/N16 -> 914864.5
D33: average
D38: MSE | E38: Mean squar Error
D39: SST | E39: Total Sum Of the Sqaure
D40: SSR | E40: Regression/resudual Sum of the Square
D41: SSE | E41: Sum of the square Error, residual
D42: MSR | E42: Mean squar Regression
D44: SST | I44: SST=SSE+SSR
E46: SST measures the total variance in the dependent variable (y).
E47: It represents the total spread of the actual values around the mean (yˉ​).
E48: SST is used to calculate the R² (coefficient of determination).
F50: Y(hat)=50,000+150×X
F52: where:
F54: X= House Size in sq ft
F55: Y(hat)= Predicted Price
F56: The model says for every extra square foot, the price increases by $150.
E58: If SST is large, prices vary a lot.
E59: If SST is small, prices are similar.
E60: Let | F60: SST | G60: 300000
E61: Since SST is large, the house prices vary significantly.
D64: SSR
...
